<?xml version="1.0" encoding="utf-8"?>
<!-- This URDF was automatically created by SolidWorks to URDF Exporter! Originally created by Stephen Brawner (brawner@gmail.com) 
     Commit Version: 1.6.0-1-g15f4949  Build Version: 1.6.7594.29634
     For more information, please see http://wiki.ros.org/sw_urdf_exporter -->
<robot
  name="hyleg_description">
  <link
    name="base_link">
    <inertial>
      <origin
        xyz="-0.00189360692020032 2.3503970908445E-08 0.476981630876272"
        rpy="0 0 0" />
      <mass
        value="1.78172861574279" />
      <inertia
        ixx="0.0157193595042145"
        ixy="4.03458809473837E-10"
        ixz="7.77942373683245E-07"
        iyy="0.0134755990716162"
        iyz="1.38092999151782E-10"
        izz="0.0280832939636086" />
    </inertial>
    <visual>
      <origin
        xyz="0 0 0"
        rpy="0 0 0" />
      <geometry>
        <mesh
          filename="package://hyleg_description/meshes/base_link.STL" />
      </geometry>
      <material
        name="">
        <color
          rgba="0.898039215686275 0.917647058823529 0.929411764705882 1" />
      </material>
    </visual>
    <collision>
      <origin
        xyz="0 0 0"
        rpy="0 0 0" />
      <geometry>
        <mesh
          filename="package://hyleg_description/meshes/base_link.STL" />
      </geometry>
    </collision>
  </link>
  <link
    name="Left_Link1">
    <inertial>
      <origin
        xyz="0.0789283207883215 0.00528249137468846 -0.0640403328645276"
        rpy="0 0 0" />
      <mass
        value="0.922870675880155" />
      <inertia
        ixx="0.000603937980956197"
        ixy="-0.000174003241138871"
        ixz="3.48802270746673E-07"
        iyy="0.00123111274771293"
        iyz="1.10518103186495E-07"
        izz="0.00154943201224718" />
    </inertial>
    <visual>
      <origin
        xyz="0 0 0"
        rpy="0 0 0" />
      <geometry>
        <mesh
          filename="package://hyleg_description/meshes/Left_Link1.STL" />
      </geometry>
      <material
        name="">
        <color
          rgba="0.792156862745098 0.819607843137255 0.933333333333333 1" />
      </material>
    </visual>
    <collision>
      <origin
        xyz="0 0 0"
        rpy="0 0 0" />
      <geometry>
        <mesh
          filename="package://hyleg_description/meshes/Left_Link1.STL" />
      </geometry>
    </collision>
  </link>
  <joint
    name="joint1"
    type="continuous">
    <origin
      xyz="3.9058E-05 -0.1776 0.44229"
      rpy="1.5708 0.7854 0" />
    <parent
      link="base_link" />
    <child
      link="Left_Link1" />
    <axis
      xyz="0 0 -1" />
  </joint>
  <link
    name="Left_Link2">
    <inertial>
      <origin
        xyz="0.00701592304090226 -0.00816888372407007 -0.0119533382148835"
        rpy="0 0 0" />
      <mass
        value="0.0574038646002277" />
      <inertia
        ixx="1.85567649161845E-05"
        ixy="-4.31736544890542E-06"
        ixz="-3.24971748797356E-07"
        iyy="1.91028896032956E-05"
        iyz="3.7925725589571E-07"
        izz="3.05314063218276E-05" />
    </inertial>
    <visual>
      <origin
        xyz="0 0 0"
        rpy="0 0 0" />
      <geometry>
        <mesh
          filename="package://hyleg_description/meshes/Left_Link2.STL" />
      </geometry>
      <material
        name="">
        <color
          rgba="0.792156862745098 0.819607843137255 0.933333333333333 1" />
      </material>
    </visual>
    <collision>
      <origin
        xyz="0 0 0"
        rpy="0 0 0" />
      <geometry>
        <mesh
          filename="package://hyleg_description/meshes/Left_Link2.STL" />
      </geometry>
    </collision>
  </link>
  <joint
    name="joint2"
    type="continuous">
    <origin
      xyz="0 0 -0.0693"
      rpy="0 0 0" />
    <parent
      link="Left_Link1" />
    <child
      link="Left_Link2" />
    <axis
      xyz="0 0 -1" />
  </joint>
  <link
    name="Left_Link4">
    <inertial>
      <origin
        xyz="0.150000000000002 8.88178419700125E-16 -2.77555756156289E-16"
        rpy="0 0 0" />
      <mass
        value="0.0249904323097953" />
      <inertia
        ixx="6.19005920434776E-07"
        ixy="-8.46106504968241E-19"
        ixz="-1.00615183181565E-19"
        iyy="7.99002270685314E-05"
        iyz="1.35342977889062E-22"
        izz="8.00741637052169E-05" />
    </inertial>
    <visual>
      <origin
        xyz="0 0 0"
        rpy="0 0 0" />
      <geometry>
        <mesh
          filename="package://hyleg_description/meshes/Left_Link4.STL" />
      </geometry>
      <material
        name="">
        <color
          rgba="0.792156862745098 0.819607843137255 0.933333333333333 1" />
      </material>
    </visual>
    <collision>
      <origin
        xyz="0 0 0"
        rpy="0 0 0" />
      <geometry>
        <mesh
          filename="package://hyleg_description/meshes/Left_Link4.STL" />
      </geometry>
    </collision>
  </link>
  <joint
    name="join12"
    type="continuous">
    <origin
      xyz="0 -0.06 -0.0168"
      rpy="-3.1416 0 0" />
    <parent
      link="Left_Link2" />
    <child
      link="Left_Link4" />
    <axis
      xyz="0 0 -1" />
  </joint>
  <link
    name="Left_Link3">
    <inertial>
      <origin
        xyz="0.120290874468717 0.0157235597190465 5.02885727504676E-08"
        rpy="0 0 0" />
      <mass
        value="0.190634570256281" />
      <inertia
        ixx="5.83166861703397E-05"
        ixy="5.21798134995358E-05"
        ixz="8.45318102107389E-11"
        iyy="0.000589701719543423"
        iyz="-5.33543298155066E-11"
        izz="0.000609708381099523" />
    </inertial>
    <visual>
      <origin
        xyz="0 0 0"
        rpy="0 0 0" />
      <geometry>
        <mesh
          filename="package://hyleg_description/meshes/Left_Link3.STL" />
      </geometry>
      <material
        name="">
        <color
          rgba="0.984313725490196 1 0.196078431372549 1" />
      </material>
    </visual>
    <collision>
      <origin
        xyz="0 0 0"
        rpy="0 0 0" />
      <geometry>
        <mesh
          filename="package://hyleg_description/meshes/Left_Link3.STL" />
      </geometry>
    </collision>
  </link>
  <joint
    name="joint11"
    type="continuous">
    <origin
      xyz="0.3 0 -0.0861"
      rpy="0 0 -1.5708" />
    <parent
      link="Left_Link1" />
    <child
      link="Left_Link3" />
    <axis
      xyz="0 0 -1" />
  </joint>
  <link
    name="Right_Link1">
    <inertial>
      <origin
        xyz="0.0789282330953898 -0.00528248948328988 -0.0640403429291297"
        rpy="0 0 0" />
      <mass
        value="0.922870134883727" />
      <inertia
        ixx="0.000603937918526634"
        ixy="0.000174003237129537"
        ixz="3.48956308184328E-07"
        iyy="0.00123111260676014"
        iyz="-1.10606481968919E-07"
        izz="0.00154943169325789" />
    </inertial>
    <visual>
      <origin
        xyz="0 0 0"
        rpy="0 0 0" />
      <geometry>
        <mesh
          filename="package://hyleg_description/meshes/Right_Link1.STL" />
      </geometry>
      <material
        name="">
        <color
          rgba="0.792156862745098 0.819607843137255 0.933333333333333 1" />
      </material>
    </visual>
    <collision>
      <origin
        xyz="0 0 0"
        rpy="0 0 0" />
      <geometry>
        <mesh
          filename="package://hyleg_description/meshes/Right_Link1.STL" />
      </geometry>
    </collision>
  </link>
  <joint
    name="joint3"
    type="continuous">
    <origin
      xyz="3.9058E-05 0.1776 0.44229"
      rpy="-1.5708 0.7854 0" />
    <parent
      link="base_link" />
    <child
      link="Right_Link1" />
    <axis
      xyz="0 0 -1" />
  </joint>
  <link
    name="Right_Link2">
    <inertial>
      <origin
        xyz="0.00701592304090227 0.00816888372406999 -0.0119533382148835"
        rpy="0 0 0" />
      <mass
        value="0.0574038646002277" />
      <inertia
        ixx="1.85567649161845E-05"
        ixy="4.31736544890541E-06"
        ixz="-3.24971748797341E-07"
        iyy="1.91028896032956E-05"
        iyz="-3.79257255895721E-07"
        izz="3.05314063218275E-05" />
    </inertial>
    <visual>
      <origin
        xyz="0 0 0"
        rpy="0 0 0" />
      <geometry>
        <mesh
          filename="package://hyleg_description/meshes/Right_Link2.STL" />
      </geometry>
      <material
        name="">
        <color
          rgba="0.792156862745098 0.819607843137255 0.933333333333333 1" />
      </material>
    </visual>
    <collision>
      <origin
        xyz="0 0 0"
        rpy="0 0 0" />
      <geometry>
        <mesh
          filename="package://hyleg_description/meshes/Right_Link2.STL" />
      </geometry>
    </collision>
  </link>
  <joint
    name="joint4"
    type="continuous">
    <origin
      xyz="0 0 -0.0693"
      rpy="0 0 0" />
    <parent
      link="Right_Link1" />
    <child
      link="Right_Link2" />
    <axis
      xyz="0 0 -1" />
  </joint>
  <link
    name="Right_Link4">
    <inertial>
      <origin
        xyz="0.150000000000003 -7.49400541621981E-16 -1.94289029309402E-16"
        rpy="0 0 0" />
      <mass
        value="0.0249904323097953" />
      <inertia
        ixx="6.19005920434817E-07"
        ixy="8.33348071200223E-19"
        ixz="-1.0989605815878E-19"
        iyy="7.99002270685315E-05"
        iyz="5.19432685142829E-23"
        izz="8.0074163705217E-05" />
    </inertial>
    <visual>
      <origin
        xyz="0 0 0"
        rpy="0 0 0" />
      <geometry>
        <mesh
          filename="package://hyleg_description/meshes/Right_Link4.STL" />
      </geometry>
      <material
        name="">
        <color
          rgba="0.792156862745098 0.819607843137255 0.933333333333333 1" />
      </material>
    </visual>
    <collision>
      <origin
        xyz="0 0 0"
        rpy="0 0 0" />
      <geometry>
        <mesh
          filename="package://hyleg_description/meshes/Right_Link4.STL" />
      </geometry>
    </collision>
  </link>
  <joint
    name="joint22"
    type="continuous">
    <origin
      xyz="0 0.06 -0.0168"
      rpy="-3.1416 0 0" />
    <parent
      link="Right_Link2" />
    <child
      link="Right_Link4" />
    <axis
      xyz="0 0 -1" />
  </joint>
  <link
    name="Right_Link3">
    <inertial>
      <origin
        xyz="0.120290770266935 -0.0157235854138926 5.75236467348361E-08"
        rpy="0 0 0" />
      <mass
        value="0.190633901636453" />
      <inertia
        ixx="5.83168066576476E-05"
        ixy="-5.21794465081896E-05"
        ixz="-2.09498545080488E-10"
        iyy="0.000589700592501225"
        iyz="-1.63109320840759E-10"
        izz="0.000609707051116941" />
    </inertial>
    <visual>
      <origin
        xyz="0 0 0"
        rpy="0 0 0" />
      <geometry>
        <mesh
          filename="package://hyleg_description/meshes/Right_Link3.STL" />
      </geometry>
      <material
        name="">
        <color
          rgba="0.984313725490196 1 0.196078431372549 1" />
      </material>
    </visual>
    <collision>
      <origin
        xyz="0 0 0"
        rpy="0 0 0" />
      <geometry>
        <mesh
          filename="package://hyleg_description/meshes/Right_Link3.STL" />
      </geometry>
    </collision>
  </link>
  <joint
    name="joint21"
    type="continuous">
    <origin
      xyz="0.3 0 -0.0861"
      rpy="0 0 1.5708" />
    <parent
      link="Right_Link1" />
    <child
      link="Right_Link3" />
    <axis
      xyz="0 0 -1" />
  </joint>
</robot>